<?xml version="1.0"?>
<robot name="mobilearmbot">

        <material name ="blue">
                <color rgba="0 0 0.1 1"/>
        </material>

        <material name="black">
                <color rgba="0 0 0 1"/>
        </material>

        <material name="white">
                <color rgba="1 1 1 1"/>
        </material>
	

	<!-- Base link --> 
	<link name="base_link">
		<visual>
			<origin rpy="0 0 0" xyz="0 0 0"/>
			<geometry>
				<box size="0.3 0.3 0.15"/>
			</geometry>
			<material name="white"/>
		</visual>
		<collision>
			<origin rpy="0 0 0" xyz="0 0 0"/>
			<geometry>
				<box size="0.3 0.3 0.15"/>
			</geometry>
		</collision>
		<inertial>
			<mass value="3.0"/>
			<inertia ixx="0.0281" ixy="0.0" ixz="0.0" iyy="0.0281" iyz="0.0" izz="0.045"/>
		</inertial>	
	</link>

	<!-- Right front wheel -->
	<link name="right_front_wheel">
		<visual>
			<origin rpy="1.57 0 0" xyz="0 0 0"/>
			<geometry>
				<cylinder length="0.05" radius="0.05"/>
			</geometry>
			<material name="black"/>
		</visual>
		<collision>
			<origin rpy="1.57 0 0" xyz="0 0 0"/>
			<geometry>
				<cylinder length="0.05" radius="0.05"/>
			</geometry>
		</collision>
		<inertial>
			<mass value="0.1"/>
			<inertia ixx="8.33e-05" ixy="0" ixz="0" iyy="8.33e-05" iyz="0" izz="1.25e-04"/> 
		</inertial>
	</link>
	<joint name="right_front_wheel_joint" type="continuous">
		<parent link="base_link"/>
		<child link="right_front_wheel"/>
		<origin xyz="0.075 -0.155 -0.075" rpy="0 0 0"/>
		<axis xyz="0 1 0"/>
	</joint>
	<gazebo reference="right_front_wheel">
		<mu1 value="0.1"/>
		<mu2 value="0.1"/>
		<kp value="10000.0"/>
		<kd value="1.0"/>
		<material>Gazebo/Black</material>
	</gazebo>
	<transmission name="right_front_wheel_trans">
		<type>transmission_interface/SimpleTransmission</type>
		<actuator name="right_front_wheel_motor">
			<mechanicalReduction>1</mechanicalReduction>
		</actuator>
		<joint name="right_front_wheel_joint">
			<hardwareInterface>VelocityJointInterface</hardwareInterface>
		</joint>
	</transmission>

	<!-- Right back wheel -->
	<link name="right_back_wheel">
		<visual>
			<origin rpy="1.57 0 0" xyz="0 0 0"/>
			<geometry>
				<cylinder length="0.05" radius="0.05"/>
			</geometry>
			<material name="black"/>
		</visual>
		<collision>
			<origin rpy="1.57 0 0" xyz="0 0 0"/>
			<geometry>
				<cylinder length="0.05" radius="0.05"/>
			</geometry>
		</collision>
		<inertial>
			<mass value="0.1"/>
			<inertia ixx="8.33e-05" ixy="0" ixz="0" iyy="8.33e-05" iyz="0" izz="1.25e-04"/>
		</inertial>
	</link>
	<joint name="right_back_wheel_joint" type="continuous">
		<parent link="base_link"/>
		<child link="right_back_wheel"/>
		<origin xyz="-0.075 -0.155 -0.075" rpy="0 0 0"/>
		<axis xyz="0 1 0"/>
	</joint>
        <gazebo reference="right_back_wheel">
                <mu1 value="0.1"/>
                <mu2 value="0.1"/>
                <kp value="10000.0"/>
                <kd value="1.0"/>
                <material>Gazebo/Black</material>
        </gazebo>
        <transmission name="right_back_wheel_trans">
                <type>transmission_interface/SimpleTransmission</type>
                <actuator name="right_back_wheel_motor">
                        <mechanicalReduction>1</mechanicalReduction>
                </actuator>
                <joint name="right_back_wheel_joint">
                        <hardwareInterface>VelocityJointInterface</hardwareInterface>
                </joint>
        </transmission>


	<!-- Left front wheel -->
	<link name="left_front_wheel">
		<visual>
			<origin rpy="1.57 0 0" xyz="0 0 0"/>
			<geometry>
				<cylinder length="0.05" radius="0.05"/>
			</geometry>
			<material name="black"/>
		</visual>
		<collision>
			<origin rpy="1.57 0 0" xyz="0 0 0"/>
			<geometry>
				<cylinder length="0.05" radius="0.05"/>
			</geometry>
		</collision>
		<inertial>
			<mass value="0.1"/>
			<inertia ixx="8.33e-05" ixy="0" ixz="0" iyy="8.33e-05" iyz="0" izz="1.25e-04"/> 
		</inertial>
	</link>
	<joint name="left_front_wheel_joint" type="continuous">
		<parent link="base_link"/>
		<child link="left_front_wheel"/>
		<origin xyz="0.075 0.155 -0.075" rpy="0 0 0"/>
		<axis xyz="0 1 0"/>
	</joint>
        <gazebo reference="left_front_wheel">
                <mu1 value="0.1"/>
                <mu2 value="0.1"/>
                <kp value="10000.0"/>
                <kd value="1.0"/>
                <material>Gazebo/Black</material>
        </gazebo>
        <transmission name="left_front_wheel_trans">
                <type>transmission_interface/SimpleTransmission</type>
                <actuator name="left_front_wheel_motor">
                        <mechanicalReduction>1</mechanicalReduction>
                </actuator>
                <joint name="left_front_wheel_joint">
                        <hardwareInterface>VelocityJointInterface</hardwareInterface>
                </joint>
        </transmission>

	<!-- Left back wheel -->
	<link name="left_back_wheel">
		<visual>
			<origin rpy="1.57 0 0" xyz="0 0 0"/>
			<geometry>
				<cylinder length="0.05" radius="0.05"/>
			</geometry>
			<material name="black"/>
		</visual>
		<collision>
			<origin rpy="1.57 0 0" xyz="0 0 0"/>
			<geometry>
				<cylinder length="0.05" radius="0.05"/>
			</geometry>
		</collision>
		<inertial>
			<mass value="0.1"/>
			<inertia ixx="8.33e-05" ixy="0" ixz="0" iyy="8.33e-05" iyz="0" izz="1.25e-04"/> 
		</inertial>
	</link>
	<joint name="left_back_wheel_joint" type="continuous">
		<parent link="base_link"/>
		<child link="left_back_wheel"/>
		<origin xyz="-0.075 0.155 -0.075" rpy="0 0 0"/>
		<axis xyz="0 1 0"/>
	</joint>
        <gazebo reference="left_back_wheel">
                <mu1 value="0.1"/>
                <mu2 value="0.1"/>
                <kp value="10000.0"/>
                <kd value="1.0"/>
                <material>Gazebo/Black</material>
        </gazebo>
        <transmission name="left_back_wheel_trans">
                <type>transmission_interface/SimpleTransmission</type>
                <actuator name="left_back_wheel_motor">
                        <mechanicalReduction>1</mechanicalReduction>
                </actuator>
                <joint name="left_back_wheel_joint">
                        <hardwareInterface>VelocityJointInterface</hardwareInterface>
                </joint>
	</transmission>

	<gazebo>
		<plugin name="gazebo_ros_control" filename="ibgazebo_ros_control.so">
			<robotNamespace>/</robotNamespace>
		</plugin>
	</gazebo>
</robot>
