<?xml version="1.0" encoding="utf-8"?>
<!-- =================================================================================== -->
<!-- |    This document was autogenerated by xacro from mobilearmbot.urdf.xacro        | -->
<!-- |    EDITING THIS FILE BY HAND IS NOT RECOMMENDED                                 | -->
<!-- =================================================================================== -->
<robot name="mobilearmbot" xmlns:xacro="http://ros.org/wiki/xacro">
  <material name="blue">
    <color rgba="0 0 0.1 1"/>
  </material>
  <material name="black">
    <color rgba="0 0 0 1"/>
  </material>
  <material name="white">
    <color rgba="1 1 1 1"/>
  </material>
  <gazebo reference="base_link">
    <material>Gazebo/Grey</material>
  </gazebo>
  <gazebo reference="right_front_wheel">
    <material>Gazebo/Black</material>
  </gazebo>
  <gazebo reference="right_back_wheel">
    <material>Gazebo/Black</material>
  </gazebo>
  <gazebo reference="left_front_wheel">
    <material>Gazebo/Black</material>
  </gazebo>
  <gazebo reference="left_back_wheel">
    <material>Gazebo/Black</material>
  </gazebo>
  <gazebo reference="arm_link1">
    <material>Gazebo/Black</material>
  </gazebo>
  <gazebo reference="arm_link2">
    <material>Gazebo/Black</material>
  </gazebo>
  <gazebo reference="arm_link3">
    <material>Gazebo/Black</material>
  </gazebo>
  <gazebo reference="left_end_effector">
    <material>Gazebo/Grey</material>
  </gazebo>
  <gazebo reference="right_end_effector">
    <material>Gazebo/Grey</material>
  </gazebo>
  <gazebo reference="base_scan">
    <material>Gazebo/Black</material>
    <sensor name="laserscan" type="ray">
      <pose>0 0 0 0 0 0</pose>
      <visualize>false</visualize>
      <update_rate>10</update_rate>
      <ray>
        <scan>
          <horizontal>
            <samples>360</samples>
            <resolution>1</resolution>
            <min_angle>0.0</min_angle>
            <max_angle>6.28</max_angle>
          </horizontal>
        </scan>
        <range>
          <min>0.3</min>
          <max>30.0</max>
          <resolution>0.015</resolution>
        </range>
        <noise>
          <type>gaussian</type>
          <mean>0</mean>
          <stddev>0.01</stddev>
        </noise>
      </ray>
      <plugin filename="libgazebo_ros_laser.so" name="mobilearmbot_laserscan_controller">
        <topicName>scan</topicName>
        <frameName>base_scan</frameName>
      </plugin>
    </sensor>
  </gazebo>
  <gazebo>
    <plugin filename="libgazebo_ros_skid_steer_drive.so" name="mobilearmbot_controller">
      <updateRate>30.0</updateRate>
      <leftFrontJoint>left_front_wheel_joint</leftFrontJoint>
      <rightFrontJoint>right_front_wheel_joint</rightFrontJoint>
      <leftRearJoint>left_back_wheel_joint</leftRearJoint>
      <rightRearJoint>right_back_wheel_joint</rightRearJoint>
      <wheelSeparation>0.67</wheelSeparation>
      <wheelDiameter>0.1</wheelDiameter>
      <robotBaseFrame>base_link</robotBaseFrame>
      <torque>20</torque>
      <topicName>cmd_vel</topicName>
      <odometryTopic>odom</odometryTopic>
      <odometryFrame>odom</odometryFrame>
      <odometrySource>world</odometrySource>
      <publishOdomTF>true</publishOdomTF>
      <publishWheelJointState>true</publishWheelJointState>
      <broadcastTF>true</broadcastTF>
    </plugin>
  </gazebo>
  <gazebo>
    <plugin filename="libgazebo_ros_control.so" name="gazebo_ros_control">
		</plugin>
  </gazebo>
  <!--Fixed Frame-->
  <link name="odom">
	</link>
  <!-- Base link -->
  <link name="base_link">
    <visual>
      <origin rpy="0 0 0" xyz="0 0 0"/>
      <geometry>
        <box size="0.3 0.3 0.15"/>
      </geometry>
      <material name="white"/>
    </visual>
    <collision>
      <origin rpy="0 0 0" xyz="0 0 0"/>
      <geometry>
        <box size="0.3 0.3 0.15"/>
      </geometry>
    </collision>
    <inertial>
      <mass value="3.0"/>
      <inertia ixx="0.028125" ixy="0.0" ixz="0.0" iyy="0.045" iyz="0.0" izz="0.028125"/>
    </inertial>
  </link>
  <joint name="odom_joint" type="fixed">
    <parent link="odom"/>
    <child link="base_link"/>
  </joint>
  <!-- Right front wheel -->
  <link name="right_front_wheel">
    <visual>
      <origin rpy="1.57075 0 0" xyz="0 0 0"/>
      <geometry>
        <cylinder length="0.05" radius="0.05"/>
      </geometry>
      <material name="black"/>
    </visual>
    <collision>
      <origin rpy="1.57075 0 0" xyz="0 0 0"/>
      <geometry>
        <cylinder length="0.05" radius="0.05"/>
      </geometry>
    </collision>
    <inertial>
      <mass value="1"/>
      <inertia ixx="0.000833333333333" ixy="0.0" ixz="0.0" iyy="0.000833333333333" iyz="0.0" izz="0.00125"/>
    </inertial>
  </link>
  <joint name="right_front_wheel_joint" type="continuous">
    <parent link="base_link"/>
    <child link="right_front_wheel"/>
    <origin rpy="0 0 0" xyz="0.1 -0.17 -0.06"/>
    <axis xyz="0 1 0"/>
    <dynamics damping="0.0"/>
  </joint>
  <transmission name="trans_right_front_wheel_joint">
    <type>transmission_interface/SimpleTransmission</type>
    <joint name="right_front_wheel_joint">
      <hardwareInterface>hardware_interface/PositionJointInterface</hardwareInterface>
    </joint>
    <actuator name="right_front_wheel_joint_motor">
      <hardwareInterface>hardware_interface/PositionJointInterface</hardwareInterface>
      <mechanicalReduction>1</mechanicalReduction>
    </actuator>
  </transmission>
  <!-- Right back wheel -->
  <link name="right_back_wheel">
    <visual>
      <origin rpy="1.57075 0 0" xyz="0 0 0"/>
      <geometry>
        <cylinder length="0.05" radius="0.05"/>
      </geometry>
      <material name="black"/>
    </visual>
    <collision>
      <origin rpy="1.57075 0 0" xyz="0 0 0"/>
      <geometry>
        <cylinder length="0.05" radius="0.05"/>
      </geometry>
    </collision>
    <inertial>
      <mass value="1"/>
      <inertia ixx="0.000833333333333" ixy="0.0" ixz="0.0" iyy="0.000833333333333" iyz="0.0" izz="0.00125"/>
    </inertial>
  </link>
  <joint name="right_back_wheel_joint" type="continuous">
    <parent link="base_link"/>
    <child link="right_back_wheel"/>
    <origin rpy="0 0 0" xyz="-0.1 -0.17 -0.06"/>
    <axis xyz="0 1 0"/>
    <dynamics damping="0.0"/>
  </joint>
  <transmission name="trans_right_back_wheel_joint">
    <type>transmission_interface/SimpleTransmission</type>
    <joint name="right_back_wheel_joint">
      <hardwareInterface>hardware_interface/PositionJointInterface</hardwareInterface>
    </joint>
    <actuator name="right_back_wheel_joint_motor">
      <hardwareInterface>hardware_interface/PositionJointInterface</hardwareInterface>
      <mechanicalReduction>1</mechanicalReduction>
    </actuator>
  </transmission>
  <!-- Left front wheel -->
  <link name="left_front_wheel">
    <visual>
      <origin rpy="1.57075 0 0" xyz="0 0 0"/>
      <geometry>
        <cylinder length="0.05" radius="0.05"/>
      </geometry>
      <material name="black"/>
    </visual>
    <collision>
      <origin rpy="1.57075 0 0" xyz="0 0 0"/>
      <geometry>
        <cylinder length="0.05" radius="0.05"/>
      </geometry>
    </collision>
    <inertial>
      <mass value="1"/>
      <inertia ixx="0.000833333333333" ixy="0.0" ixz="0.0" iyy="0.000833333333333" iyz="0.0" izz="0.00125"/>
    </inertial>
  </link>
  <joint name="left_front_wheel_joint" type="continuous">
    <parent link="base_link"/>
    <child link="left_front_wheel"/>
    <origin rpy="0 0 0" xyz="0.1 0.17 -0.06"/>
    <axis xyz="0 1 0"/>
    <dynamics damping="0.0"/>
  </joint>
  <transmission name="trans_left_front_wheel_joint">
    <type>transmission_interface/SimpleTransmission</type>
    <joint name="left_front_wheel_joint">
      <hardwareInterface>hardware_interface/PositionJointInterface</hardwareInterface>
    </joint>
    <actuator name="left_front_wheel_joint_motor">
      <hardwareInterface>hardware_interface/PositionJointInterface</hardwareInterface>
      <mechanicalReduction>1</mechanicalReduction>
    </actuator>
  </transmission>
  <!-- Left back wheel -->
  <link name="left_back_wheel">
    <visual>
      <origin rpy="1.57075 0 0" xyz="0 0 0"/>
      <geometry>
        <cylinder length="0.05" radius="0.05"/>
      </geometry>
      <material name="black"/>
    </visual>
    <collision>
      <origin rpy="1.57075 0 0" xyz="0 0 0"/>
      <geometry>
        <cylinder length="0.05" radius="0.05"/>
      </geometry>
    </collision>
    <inertial>
      <mass value="1"/>
      <inertia ixx="0.000833333333333" ixy="0.0" ixz="0.0" iyy="0.000833333333333" iyz="0.0" izz="0.00125"/>
    </inertial>
  </link>
  <joint name="left_back_wheel_joint" type="continuous">
    <parent link="base_link"/>
    <child link="left_back_wheel"/>
    <origin rpy="0 0 0" xyz="-0.1 0.17 -0.06"/>
    <axis xyz="0 1 0"/>
    <dynamics damping="0.0"/>
  </joint>
  <transmission name="trans_left_back_wheel_joint">
    <type>transmission_interface/SimpleTransmission</type>
    <joint name="left_back_wheel_joint">
      <hardwareInterface>hardware_interface/PositionJointInterface</hardwareInterface>
    </joint>
    <actuator name="left_back_wheel_joint_motor">
      <hardwareInterface>hardware_interface/PositionJointInterface</hardwareInterface>
      <mechanicalReduction>1</mechanicalReduction>
    </actuator>
  </transmission>
  <link name="base_scan">
    <visual>
      <origin rpy="0 0 0" xyz="0 0 0"/>
      <geometry>
        <box size="0.05 0.05 0.05"/>
      </geometry>
      <material name="blue"/>
    </visual>
    <collision>
      <origin rpy="0 0 0" xyz="0 0 0"/>
      <geometry>
        <box size="0.05 0.05 0.05"/>
      </geometry>
    </collision>
    <inertial>
      <mass value="0.1"/>
      <inertia ixx="4.16666666667e-05" ixy="0.0" ixz="0.0" iyy="4.16666666667e-05" iyz="0.0" izz="4.16666666667e-05"/>
    </inertial>
  </link>
  <joint name="base_scan_joint" type="fixed">
    <parent link="base_link"/>
    <child link="base_scan"/>
    <origin rpy="0 0 0" xyz="0.0 0 0.1"/>
  </joint>
  <link name="arm_link1">
    <visual>
      <origin rpy="0 0 0" xyz="0 0 0.15"/>
      <geometry>
        <cylinder length="0.3" radius="0.05"/>
      </geometry>
    </visual>
    <collision>
      <origin rpy="0 0 0" xyz="0 0 0.15"/>
      <geometry>
        <cylinder length="0.3" radius="0.05"/>
      </geometry>
    </collision>
    <inertial>
      <mass value="1.2"/>
      <inertia ixx="0.00975" ixy="0.0" ixz="0.0" iyy="0.00975" iyz="0.0" izz="0.0015"/>
    </inertial>
  </link>
  <joint name="arm_link1_joint" type="continuous">
    <parent link="base_link"/>
    <child link="arm_link1"/>
    <origin rpy="0 0 0" xyz="-0.075 0 0.075"/>
    <axis xyz="0 0 1"/>
  </joint>
  <transmission name="trans_arm_link1_joint">
    <type>transmission_interface/SimpleTransmission</type>
    <joint name="arm_link1_joint">
      <hardwareInterface>hardware_interface/PositionJointInterface</hardwareInterface>
    </joint>
    <actuator name="arm_link1_joint_motor">
      <hardwareInterface>hardware_interface/PositionJointInterface</hardwareInterface>
      <mechanicalReduction>1</mechanicalReduction>
    </actuator>
  </transmission>
  <link name="arm_link2">
    <visual>
      <origin rpy="0 0 0" xyz="0 0 0.2"/>
      <geometry>
        <cylinder length="0.4" radius="0.05"/>
      </geometry>
    </visual>
    <collision>
      <origin rpy="0 0 0" xyz="0 0 0.2"/>
      <geometry>
        <cylinder length="0.4" radius="0.05"/>
      </geometry>
    </collision>
    <inertial>
      <mass value="1.6"/>
      <inertia ixx="0.0223333333333" ixy="0.0" ixz="0.0" iyy="0.0223333333333" iyz="0.0" izz="0.002"/>
    </inertial>
  </link>
  <joint name="arm_link2_joint" type="continuous">
    <parent link="arm_link1"/>
    <child link="arm_link2"/>
    <origin rpy="0 1.57075 0" xyz="0 0 0.3"/>
    <axis xyz="0 1 0"/>
  </joint>
  <transmission name="trans_arm_link2_joint">
    <type>transmission_interface/SimpleTransmission</type>
    <joint name="arm_link2_joint">
      <hardwareInterface>hardware_interface/PositionJointInterface</hardwareInterface>
    </joint>
    <actuator name="arm_link2_joint_motor">
      <hardwareInterface>hardware_interface/PositionJointInterface</hardwareInterface>
      <mechanicalReduction>1</mechanicalReduction>
    </actuator>
  </transmission>
  <link name="arm_link3">
    <visual>
      <origin rpy="0 0 0" xyz="0 0 0.1"/>
      <geometry>
        <cylinder length="0.2" radius="0.05"/>
      </geometry>
    </visual>
    <collision>
      <origin rpy="0 0 0" xyz="0 0 0.1"/>
      <geometry>
        <cylinder length="0.2" radius="0.05"/>
      </geometry>
    </collision>
    <inertial>
      <mass value="0.8"/>
      <inertia ixx="0.00316666666667" ixy="0.0" ixz="0.0" iyy="0.00316666666667" iyz="0.0" izz="0.001"/>
    </inertial>
  </link>
  <joint name="arm_link3_joint" type="continuous">
    <parent link="arm_link2"/>
    <child link="arm_link3"/>
    <origin rpy="0 1.57075 0" xyz="0 0 0.4"/>
    <axis xyz="0 1 0"/>
  </joint>
  <transmission name="trans_arm_link3_joint">
    <type>transmission_interface/SimpleTransmission</type>
    <joint name="arm_link3_joint">
      <hardwareInterface>hardware_interface/PositionJointInterface</hardwareInterface>
    </joint>
    <actuator name="arm_link3_joint_motor">
      <hardwareInterface>hardware_interface/PositionJointInterface</hardwareInterface>
      <mechanicalReduction>1</mechanicalReduction>
    </actuator>
  </transmission>
  <link name="left_end_effector">
    <visual>
      <origin rpy="1.57075 1.57075 0" xyz="0 0 0.05"/>
      <geometry>
        <box size="0.1 0.05 0.01"/>
      </geometry>
    </visual>
    <collision>
      <origin rpy="1.57075 1.57075 0" xyz="0 0 0.05"/>
      <geometry>
        <box size="0.1 0.05 0.01"/>
      </geometry>
    </collision>
    <inertial>
      <mass value="0.1"/>
      <inertia ixx="8.41666666667e-05" ixy="0.0" ixz="0.0" iyy="0.000104166666667" iyz="0.0" izz="2.16666666667e-05"/>
    </inertial>
  </link>
  <joint name="left_end_effector_joint" type="continuous">
    <parent link="arm_link3"/>
    <child link="left_end_effector"/>
    <origin rpy="-1.57075 0 0" xyz="0 0.05 0.2"/>
    <axis xyz="1 0 0"/>
  </joint>
  <transmission name="trans_left_end_effector_joint">
    <type>transmission_interface/SimpleTransmission</type>
    <joint name="left_end_effector_joint">
      <hardwareInterface>hardware_interface/PositionJointInterface</hardwareInterface>
    </joint>
    <actuator name="left_end_effector_joint_motor">
      <hardwareInterface>hardware_interface/PositionJointInterface</hardwareInterface>
      <mechanicalReduction>1</mechanicalReduction>
    </actuator>
  </transmission>
  <link name="right_end_effector">
    <visual>
      <origin rpy="1.57075 1.57075 0" xyz="0 0 0.05"/>
      <geometry>
        <box size="0.1 0.05 0.01"/>
      </geometry>
    </visual>
    <collision>
      <origin rpy="1.57075 1.57075 0" xyz="0 0 0.05"/>
      <geometry>
        <box size="0.1 0.05 0.01"/>
      </geometry>
    </collision>
    <inertial>
      <mass value="0.1"/>
      <inertia ixx="8.41666666667e-05" ixy="0.0" ixz="0.0" iyy="0.000104166666667" iyz="0.0" izz="2.16666666667e-05"/>
    </inertial>
  </link>
  <joint name="right_end_effector_joint" type="continuous">
    <parent link="arm_link3"/>
    <child link="right_end_effector"/>
    <origin rpy="1.57075 0 0" xyz="0 -0.05 0.2"/>
    <axis xyz="1 0 0"/>
  </joint>
  <transmission name="trans_right_end_effector_joint">
    <type>transmission_interface/SimpleTransmission</type>
    <joint name="right_end_effector_joint">
      <hardwareInterface>hardware_interface/PositionJointInterface</hardwareInterface>
    </joint>
    <actuator name="right_end_effector_joint_motor">
      <hardwareInterface>hardware_interface/PositionJointInterface</hardwareInterface>
      <mechanicalReduction>1</mechanicalReduction>
    </actuator>
  </transmission>
</robot>

